Workbook

Sheet Sheet1
A1: Location | B1: Basic 3PL
A3: Row Labels | B3: Sum of Committed (not editable) | C3: Sum of Available (not editable) | D3: Sum of On hand (current)
A4: FD-ULGHTBNE-GRY-1 | B4: 78 | C4: 19905 | D4: 19983 | E4: =VLOOKUP(A4,Sheet2!C:D,2,FALSE) -> 85.666667
A5: FD-ULGHTBNE-BLK-1 | B5: 84 | C5: 12770 | D5: 12854 | E5: =VLOOKUP(A5,Sheet2!C:D,2,FALSE) -> 81.5
A6: FD-ULGHTBNE-NVY-1 | B6: 12 | C6: 11162 | D6: 11174 | E6: =VLOOKUP(A6,Sheet2!C:D,2,FALSE) -> 85.666667
A7: FD2-UBNE-GRY-1 | B7: 17 | C7: 7242 | D7: 7259 | E7: =VLOOKUP(A7,Sheet2!C:D,2,FALSE) -> 96
A8: FD2-UBNE-BLK-1 | B8: 32 | C8: 5555 | D8: 5587 | E8: =VLOOKUP(A8,Sheet2!C:D,2,FALSE) -> 96
A9: FD-ULGHTBNE-WHT-1 | B9: 13 | C9: 5518 | D9: 5531 | E9: =VLOOKUP(A9,Sheet2!C:D,2,FALSE) -> 81.5
A10: FD-UCAP-BLK-1 | B10: 49 | C10: 4932 | D10: 4981 | E10: =VLOOKUP(A10,Sheet2!C:D,2,FALSE) -> 101
A11: FD2-UBNE-WHT-1 | B11: 4 | C11: 1397 | D11: 1401 | E11: =VLOOKUP(A11,Sheet2!C:D,2,FALSE) -> 98
A12: FD-UCAP-LIVY-1 | B12: 2 | C12: 1217 | D12: 1219 | E12: =VLOOKUP(A12,Sheet2!C:D,2,FALSE) -> 98
A13: FD-UCAP-CSMR-1 | B13: 3 | C13: 1150 | D13: 1153 | E13: =VLOOKUP(A13,Sheet2!C:D,2,FALSE) -> 98
A14: FD2-MBRF-BLK-M | B14: 15 | C14: 1006 | D14: 1021 | E14: =VLOOKUP(A14,Sheet2!C:D,2,FALSE) -> 86
A15: FD-ULGHTBNE-GRY-TOD | B15: 3 | C15: 960 | D15: 963 | E15: =VLOOKUP(A15,Sheet2!C:D,2,FALSE) -> 77.333333
... A194: FD-WTNK-BWHT-L | B194: 0 | C194: 0 | D194: 0 | E194: =VLOOKUP(A194,Sheet2!C:D,2,FALSE) -> 99
A195: Grand Total | B195: 545 | C195: 86878 | D195: 87423

Sheet Total Inventory
A2: SKU | B2: Location | C2: Type | D2: Available Inventory | E2: On hand Inventory | F2: Price per Unit | G2: Total Value (On Hand Inventory)
A3: SKU 1 | B3: Warehouse 1 | C3: Finished Goods | D3: 19905 | E3: 19983 | F3: 14.22 | G3: =IFERROR(F3*E3,0) -> 284158.26
A4: SKU 2 | B4: Warehouse 1 | C4: Finished Goods | D4: 12770 | E4: 12854 | F4: 14.22 | G4: =IFERROR(F4*E4,0) -> 182783.88
A5: SKU 3 | B5: Warehouse 1 | C5: Finished Goods | D5: 11162 | E5: 11174 | F5: 14.22 | G5: =IFERROR(F5*E5,0) -> 158894.28
A6: SKU 4 | B6: Warehouse 1 | C6: Finished Goods | D6: 7242 | E6: 7259 | F6: 14.08 | G6: =IFERROR(F6*E6,0) -> 102206.72
A7: SKU 5 | B7: Warehouse 1 | C7: Finished Goods | D7: 5555 | E7: 5587 | F7: 14.08 | G7: =IFERROR(F7*E7,0) -> 78664.96
A8: SKU 6 | B8: Warehouse 1 | C8: Finished Goods | D8: 5518 | E8: 5531 | F8: 14.22 | G8: =IFERROR(F8*E8,0) -> 78650.82
A9: SKU 7 | B9: Warehouse 1 | C9: Finished Goods | D9: 422 | E9: 424 | F9: 153.46 | G9: =IFERROR(F9*E9,0) -> 65067.04
A10: SKU 8 | B10: Warehouse 1 | C10: Finished Goods | D10: 407 | E10: 408 | F10: 150.46 | G10: =IFERROR(F10*E10,0) -> 61387.68
A11: SKU 9 | B11: Warehouse 1 | C11: Finished Goods | D11: 406 | E11: 406 | F11: 150.46 | G11: =IFERROR(F11*E11,0) -> 61086.76
A12: SKU 10 | B12: Warehouse 1 | C12: Finished Goods | D12: 388 | E12: 393 | F12: 153.46 | G12: =IFERROR(F12*E12,0) -> 60309.78
A13: SKU 11 | B13: Warehouse 1 | C13: Finished Goods | D13: 4932 | E13: 4981 | F13: 10.48 | G13: =IFERROR(F13*E13,0) -> 52200.88
A14: SKU 12 | B14: Warehouse 1 | C14: Finished Goods | D14: 270 | E14: 276 | F14: 114.01 | G14: =IFERROR(F14*E14,0) -> 31466.76
... A118: SKU 116 | B118: Warehouse 2 | C118: Packaging | D118: 0 | E118: 1 | F118: 10.48 | G118: =IFERROR(F118*E118,0) -> 10.48
A119: SKU 117 | B119: Warehouse 2 | C119: Packaging | D119: 1 | E119: 1 | F119: TBC | G119: =IFERROR(F119*E119,0) -> 0
A120: SKU 118 | B120: Warehouse 2 | C120: Packaging | D120: 1 | E120: 1 | F120: TBC | G120: =IFERROR(F120*E120,0) -> 0
A121: SKU 119 | B121: Warehouse 2 | C121: Packaging | D121: 1 | E121: 1 | F121: TBC | G121: =IFERROR(F121*E121,0) -> 0
A122: SKU 120 | B122: Warehouse 2 | C122: Packaging | D122: 0 | E122: 2 | F122: TBC | G122: =IFERROR(F122*E122,0) -> 0
A123: Total | G123: =SUM(G3:G122) -> 1697548.5

Sheet Sheet3
A1: Product Title,Variant Title,SKU,Cost of Goods (USD) | B1: Product Title | C1: Variant Title | D1: SKU | E1: Cost of Goods (USD)
A2: WaveStopper™ Beanie,Black Ribbed,FD2-UBNE-BLK-1,14.08 | B2: WaveStopper™ Beanie | C2: Black Ribbed | D2: FD2-UBNE-BLK-1 | E2: 14.08
A3: WaveStopper™ Beanie,Grey Ribbed,FD2-UBNE-GRY-1,14.08 | B3: WaveStopper™ Beanie | C3: Grey Ribbed | D3: FD2-UBNE-GRY-1 | E3: 14.08
A4: WaveStopper™ Beanie,White Ribbed,FD2-UBNE-WHT-1,14.08 | B4: WaveStopper™ Beanie | C4: White Ribbed | D4: FD2-UBNE-WHT-1 | E4: 14.08
A5: WaveStopper™ Beanie,Blue Ribbed,FD2-UBNE-NAV-1,14.08 | B5: WaveStopper™ Beanie | C5: Blue Ribbed | D5: FD2-UBNE-NAV-1 | E5: 14.08
A6: WaveStopper™ Beanie,Chestnut Ribbed,FD2-UBNE-CHT-1,14.08 | B6: WaveStopper™ Beanie | C6: Chestnut Ribbed | D6: FD2-UBNE-CHT-1 | E6: 14.08
A7: WaveStopper™ Beanie,Beige Ribbed,FD2-UBNE-BEI-1,14.08 | B7: WaveStopper™ Beanie | C7: Beige Ribbed | D7: FD2-UBNE-BEI-1 | E7: 14.08
A8: WaveStopper™ Beanie,Forest Green,FD2-UBNE-GRN-1,14.08 | B8: WaveStopper™ Beanie | C8: Forest Green | D8: FD2-UBNE-GRN-1 | E8: 14.08
A9: WaveStopper™ Beanie,Red Ribbed,STYL1-UBNE-RD-1,14.08 | B9: WaveStopper™ Beanie | C9: Red Ribbed | D9: STYL1-UBNE-RD-1 | E9: 14.08
A10: WaveStopper™ Cap,Carbon Black,FD-UCAP-BLK-1,10.48 | B10: WaveStopper™ Cap | C10: Carbon Black | D10: FD-UCAP-BLK-1 | E10: 10.48
A11: WaveStopper™ Cap,Beige,FD-UCAP-CSMR-1,10.48 | B11: WaveStopper™ Cap | C11: Beige | D11: FD-UCAP-CSMR-1 | E11: 10.48
A12: WaveStopper™ Cap,Navy Blue,FD-UCAP-NVY-1,10.48 | B12: WaveStopper™ Cap | C12: Navy Blue | D12: FD-UCAP-NVY-1 | E12: 10.48
A13: WaveStopper™ Cap,White Ivory,FD-UCAP-LIVY-1,10.48 | B13: WaveStopper™ Cap | C13: White Ivory | D13: FD-UCAP-LIVY-1 | E13: 10.48
... A91: WaveStopper™ Lightweight Beanie,Black / Adult,FD-ULGHTBNE-BLK-1,14.22 | B91: WaveStopper™ Lightweight Beanie | C91: Black / Adult | D91: FD-ULGHTBNE-BLK-1 | E91: 14.22
A92: WaveStopper™ Lightweight Beanie,Black / Kids (3-12 Years),,14.22 | B92: WaveStopper™ Lightweight Beanie | C92: Black / Kids (3-12 Years) | D92: 14.22
A93: WaveStopper™ Lightweight Beanie,Heather Grey / Adult,FD-ULGHTBNE-GRY-1,14.22 | B93: WaveStopper™ Lightweight Beanie | C93: Heather Grey / Adult | D93: FD-ULGHTBNE-GRY-1 | E93: 14.22
A94: WaveStopper™ Lightweight Beanie,Heather Grey / Kids (3-12 Years),FD-ULGHTBNE-GRY-TOD,11.7 | B94: WaveStopper™ Lightweight Beanie | C94: Heather Grey / Kids (3-12 Years) | D94: FD-ULGHTBNE-GRY-TOD | E94: 11.7
A95: WaveStopper™ Lightweight Beanie,White / Adult,FD-ULGHTBNE-WHT-1,14.22 | B95: WaveStopper™ Lightweight Beanie | C95: White / Adult | D95: FD-ULGHTBNE-WHT-1 | E95: 14.22
A96: WaveStopper™ Lightweight Beanie,White / Kids (3-12 Years),,14.22 | B96: WaveStopper™ Lightweight Beanie | C96: White / Kids (3-12 Years) | D96: 14.22
A97: WaveStopper™ Lightweight Beanie,Navy Blue / Adult,FD-ULGHTBNE-NVY-1,14.22 | B97: WaveStopper™ Lightweight Beanie | C97: Navy Blue / Adult | D97: FD-ULGHTBNE-NVY-1 | E97: 14.22
A98: WaveStopper™ Lightweight Beanie,Navy Blue / Kids (3-12 Years),,14.22 | B98: WaveStopper™ Lightweight Beanie | C98: Navy Blue / Kids (3-12 Years) | D98: 14.22
A99: WaveStopper™ Lightweight Beanie,Dark Grey / Adult,FD-ULGHTBNE-DRKGRY-1,14.22 | B99: WaveStopper™ Lightweight Beanie | C99: Dark Grey / Adult | D99: FD-ULGHTBNE-DRKGRY-1 | E99: 14.22
A100: WaveStopper™ Lightweight Beanie,Forest Green / Adult,FD-ULGHTBNE-GRN-1,14.22 | B100: WaveStopper™ Lightweight Beanie | C100: Forest Green / Adult | D100: FD-ULGHTBNE-GRN-1 | E100: 14.22
A101: WaveStopper™ Lightweight Beanie,Forest Green / Kids (3-12 Years),,14.22 | B101: WaveStopper™ Lightweight Beanie | C101: Forest Green / Kids (3-12 Years) | D101: 14.22
A102: WaveStopper™ Lightweight Beanie,Saffron / Adult,FD-ULGHTBNE-SFN-1,14.22 | B102: WaveStopper™ Lightweight Beanie | C102: Saffron / Adult | D102: FD-ULGHTBNE-SFN-1 | E102: 14.22
A103: WaveStopper™ Lightweight Beanie,Saffron / Kids (3-12 Years),,14.22 | B103: WaveStopper™ Lightweight Beanie | C103: Saffron / Kids (3-12 Years) | D103: 14.22
A104: WaveStopper™ Lightweight Beanie,Chestnut Brown / Adult,FD-ULGHTBNE-BRWN-1,14.22 | B104: WaveStopper™ Lightweight Beanie | C104: Chestnut Brown / Adult | D104: FD-ULGHTBNE-BRWN-1 | E104: 14.22
A105: WaveStopper™ Lightweight Beanie,Chestnut Brown / Kids (3-12 Years),,14.22 | B105: WaveStopper™ Lightweight Beanie | C105: Chestnut Brown / Kids (3-12 Years) | D105: 14.22
A106: WaveStopper™ Lightweight Beanie,Beige / Adult,FD-ULGHTBNE-BEI-1,14.22 | B106: WaveStopper™ Lightweight Beanie | C106: Beige / Adult | D106: FD-ULGHTBNE-BEI-1 | E106: 14.22
A107: WaveStopper™ Lightweight Beanie,Beige / Kids (3-12 Years),,14.22 | B107: WaveStopper™ Lightweight Beanie | C107: Beige / Kids (3-12 Years) | D107: 14.22
A108: WaveStopper™ Lightweight Beanie,Dusty Rose / Adult,FD-ULGHTBNE-ROS-1,14.22 | B108: WaveStopper™ Lightweight Beanie | C108: Dusty Rose / Adult | D108: FD-ULGHTBNE-ROS-1 | E108: 14.22
A109: WaveStopper™ Lightweight Beanie,Dusty Rose / Kids (3-12 Years),,14.22 | B109: WaveStopper™ Lightweight Beanie | C109: Dusty Rose / Kids (3-12 Years) | D109: 14.22
A110: WaveStopper™ Lightweight Beanie,Slate Blue / Adult,FD-ULGHTBNE-BLU-1,14.22 | B110: WaveStopper™ Lightweight Beanie | C110: Slate Blue / Adult | D110: FD-ULGHTBNE-BLU-1 | E110: 14.22
A111: WaveStopper™ Lightweight Beanie,Slate Blue / Kids (3-12 Years),,14.22 | B111: WaveStopper™ Lightweight Beanie | C111: Slate Blue / Kids (3-12 Years) | D111: 14.22
A112: WaveStopper™ Performance Cap,Heather Grey,FD-UCAP-HGRY-1,10.48 | B112: WaveStopper™ Performance Cap | C112: Heather Grey | D112: FD-UCAP-HGRY-1 | E112: 10.48
A113: WaveStopper™ Performance Cap,Heather Black,FD-PCAP-BLK-1,10.48 | B113: WaveStopper™ Performance Cap | C113: Heather Black | D113: FD-PCAP-BLK-1 | E113: 10.48
A114: WaveStopper™ Performance Cap,Navy Blue,FD-PCAP-NVY-1,10.48 | B114: WaveStopper™ Performance Cap | C114: Navy Blue | D114: FD-PCAP-NVY-1 | E114: 10.48
A115: WaveStopper™ Performance Cap,Forest Green,FD-PCAP-FGRN-1,10.48 | B115: WaveStopper™ Performance Cap | C115: Forest Green | D115: FD-PCAP-FGRN-1 | E115: 10.48
A116: 15% CashBack - 30% Boosted,Redeem cash or credit,fondue-cashback-sku-1715041918, | B116: 15% CashBack - 30% Boosted | C116: Redeem cash or credit | D116: fondue-cashback-sku-1715041918
A117: WaveStopper™ Blanket,Beige / Premium Cotton / Medium,FD2-BLKT-BEI,81.88 | B117: WaveStopper™ Blanket | C117: Beige / Premium Cotton / Medium | D117: FD2-BLKT-BEI | E117: 81.88
...

Sheet Sheet2
C3: Row Labels | D3: Average of Variant Price
C4: antibacterial-socks-2-pack | D4: 29
C5: BBG-CLR-1 | D5: 89
C6: BBG-TTS-1 | D6: 89
C7: FD2-BLKT-BEI | D7: 318
C8: FD2-BLKT-BEI-LARG | D8: 598
C9: FD2-BLKT-BORD | D9: 318
C10: FD2-BLKT-BORD-LARG | D10: 598
C11: FD2-BLKT-GRY | D11: 318
C12: FD2-BLKT-GRY-LARG | D12: 598
C13: FD2-BLKT-NAVY | D13: 318
C14: FD2-BLKT-NAVY-LARG | D14: 598
C15: FD2-MBRF-BLK-L | D15: 86
... C200: Grand Total | D200: 182.6

Sheet inventory_export_1
A1: Handle | B1: Title | C1: Option1 Name | D1: Option1 Value | E1: Option2 Name | F1: Option2 Value | G1: Option3 Name | H1: Option3 Value | I1: SKU | J1: HS Code | K1: COO | L1: Location | M1: Bin name | N1: Incoming (not editable) | O1: Unavailable (not editable) | P1: Committed (not editable) | Q1: Available (not editable) | R1: On hand (current) | S1: On hand (new)
A2: wavestopper-blanket | B2: WaveStopperâ„¢ Blanket | C2: Color | D2: Burgundy | E2: Fabric | F2: Original SoftBlend | G2: Size | H2: Medium 59"x36" | I2: FD-BLKT-BORD | L2: Shipmonk | N2: 0 | O2: 0 | P2: 0 | Q2: 0 | R2: 0
A3: wavestopper-blanket | B3: WaveStopperâ„¢ Blanket | C3: Color | D3: Burgundy | E3: Fabric | F3: Original SoftBlend | G3: Size | H3: Medium 59"x36" | I3: FD-BLKT-BORD | L3: Santa Monica Office | N3: 0 | O3: 0 | P3: 0 | Q3: 0 | R3: 0
A4: wavestopper-blanket | B4: WaveStopperâ„¢ Blanket | C4: Color | D4: Burgundy | E4: Fabric | F4: Original SoftBlend | G4: Size | H4: Medium 59"x36" | I4: FD-BLKT-BORD | L4: Fondue Fulfillment | N4: not stocked | O4: not stocked | P4: not stocked | Q4: not stocked | R4: not stocked
A5: wavestopper-blanket | B5: WaveStopperâ„¢ Blanket | C5: Color | D5: Burgundy | E5: Fabric | F5: Original SoftBlend | G5: Size | H5: Medium 59"x36" | I5: FD-BLKT-BORD | L5: Basic 3PL | N5: 0 | O5: 0 | P5: 0 | Q5: 0 | R5: 0
A6: wavestopper-blanket | B6: WaveStopperâ„¢ Blanket | C6: Color | D6: Beige | E6: Fabric | F6: Original SoftBlend | G6: Size | H6: Medium 59"x36" | I6: FD-BLKT-BEI | L6: Shipmonk | N6: 0 | O6: 0 | P6: 0 | Q6: 0 | R6: 0
A7: wavestopper-blanket | B7: WaveStopperâ„¢ Blanket | C7: Color | D7: Beige | E7: Fabric | F7: Original SoftBlend | G7: Size | H7: Medium 59"x36" | I7: FD-BLKT-BEI | L7: Santa Monica Office | N7: 0 | O7: 0 | P7: 0 | Q7: 0 | R7: 0
A8: wavestopper-blanket | B8: WaveStopperâ„¢ Blanket | C8: Color | D8: Beige | E8: Fabric | F8: Original SoftBlend | G8: Size | H8: Medium 59"x36" | I8: FD-BLKT-BEI | L8: Fondue Fulfillment | N8: not stocked | O8: not stocked | P8: not stocked | Q8: not stocked | R8: not stocked
A9: wavestopper-blanket | B9: WaveStopperâ„¢ Blanket | C9: Color | D9: Beige | E9: Fabric | F9: Original SoftBlend | G9: Size | H9: Medium 59"x36" | I9: FD-BLKT-BEI | L9: Basic 3PL | N9: 0 | O9: 0 | P9: 0 | Q9: 0 | R9: 0
A10: wavestopper-blanket | B10: WaveStopperâ„¢ Blanket | C10: Color | D10: Royal Blue | E10: Fabric | F10: Original SoftBlend | G10: Size | H10: Large 70"x60" | I10: FD-BLKT-NAVY-LARG | L10: Shipmonk | N10: 0 | O10: 0 | P10: 0 | Q10: 0 | R10: 0
A11: wavestopper-blanket | B11: WaveStopperâ„¢ Blanket | C11: Color | D11: Royal Blue | E11: Fabric | F11: Original SoftBlend | G11: Size | H11: Large 70"x60" | I11: FD-BLKT-NAVY-LARG | L11: Santa Monica Office | N11: 0 | O11: 0 | P11: 0 | Q11: 0 | R11: 0
A12: wavestopper-blanket | B12: WaveStopperâ„¢ Blanket | C12: Color | D12: Royal Blue | E12: Fabric | F12: Original SoftBlend | G12: Size | H12: Large 70"x60" | I12: FD-BLKT-NAVY-LARG | L12: Fondue Fulfillment | N12: not stocked | O12: not stocked | P12: not stocked | Q12: not stocked | R12: not stocked
A13: wavestopper-blanket | B13: WaveStopperâ„¢ Blanket | C13: Color | D13: Royal Blue | E13: Fabric | F13: Original SoftBlend | G13: Size | H13: Large 70"x60" | I13: FD-BLKT-NAVY-LARG | L13: Basic 3PL | N13: 0 | O13: 0 | P13: 0 | Q13: 0 | R13: 0
A14: wavestopper-blanket | B14: WaveStopperâ„¢ Blanket | C14: Color | D14: Burgundy | E14: Fabric | F14: Original SoftBlend | G14: Size | H14: Large 70"x60" | I14: FD-BLKT-BORD-LARG | L14: Shipmonk | N14: 0 | O14: 0 | P14: 0 | Q14: 0 | R14: 0
A15: wavestopper-blanket | B15: WaveStopperâ„¢ Blanket | C15: Color | D15: Burgundy | E15: Fabric | F15: Original SoftBlend | G15: Size | H15: Large 70"x60" | I15: FD-BLKT-BORD-LARG | L15: Santa Monica Office | N15: 0 | O15: 0 | P15: 0 | Q15: 0 | R15: 0
A16: wavestopper-blanket | B16: WaveStopperâ„¢ Blanket | C16: Color | D16: Burgundy | E16: Fabric | F16: Original SoftBlend | G16: Size | H16: Large 70"x60" | I16: FD-BLKT-BORD-LARG | L16: Fondue Fulfillment | N16: not stocked | O16: not stocked | P16: not stocked | Q16: not stocked | R16: not stocked
A17: wavestopper-blanket | B17: WaveStopperâ„¢ Blanket | C17: Color | D17: Burgundy | E17: Fabric | F17: Original SoftBlend | G17: Size | H17: Large 70"x60" | I17: FD-BLKT-BORD-LARG | L17: Basic 3PL | N17: 0 | O17: 0 | P17: 0 | Q17: 0 | R17: 0
A18: wavestopper-blanket | B18: WaveStopperâ„¢ Blanket | C18: Color | D18: Beige | E18: Fabric | F18: Original SoftBlend | G18: Size | H18: Large 70"x60" | I18: FD-BLKT-BEI-LARG | L18: Shipmonk | N18: 0 | O18: 0 | P18: 0 | Q18: 0 | R18: 0
A19: wavestopper-blanket | B19: WaveStopperâ„¢ Blanket | C19: Color | D19: Beige | E19: Fabric | F19: Original SoftBlend | G19: Size | H19: Large 70"x60" | I19: FD-BLKT-BEI-LARG | L19: Santa Monica Office | N19: 0 | O19: 0 | P19: 0 | Q19: 0 | R19: 0
A20: wavestopper-blanket | B20: WaveStopperâ„¢ Blanket | C20: Color | D20: Beige | E20: Fabric | F20: Original SoftBlend | G20: Size | H20: Large 70"x60" | I20: FD-BLKT-BEI-LARG | L20: Fondue Fulfillment | N20: not stocked | O20: not stocked | P20: not stocked | Q20: not stocked | R20: not stocked
A21: wavestopper-blanket | B21: WaveStopperâ„¢ Blanket | C21: Color | D21: Beige | E21: Fabric | F21: Original SoftBlend | G21: Size | H21: Large 70"x60" | I21: FD-BLKT-BEI-LARG | L21: Basic 3PL | N21: 0 | O21: 0 | P21: 0 | Q21: 168 | R21: 168
A22: wavestopper-blanket | B22: WaveStopperâ„¢ Blanket | C22: Color | D22: Heather Grey | E22: Fabric | F22: Premium Cotton | G22: Size | H22: Medium 59"x36" | I22: FD2-BLKT-GRY | L22: Shipmonk | N22: 0 | O22: 0 | P22: 0 | Q22: 0 | R22: 0
A23: wavestopper-blanket | B23: WaveStopperâ„¢ Blanket | C23: Color | D23: Heather Grey | E23: Fabric | F23: Premium Cotton | G23: Size | H23: Medium 59"x36" | I23: FD2-BLKT-GRY | L23: Santa Monica Office | N23: 0 | O23: 0 | P23: 0 | Q23: 0 | R23: 0
A24: wavestopper-blanket | B24: WaveStopperâ„¢ Blanket | C24: Color | D24: Heather Grey | E24: Fabric | F24: Premium Cotton | G24: Size | H24: Medium 59"x36" | I24: FD2-BLKT-GRY | L24: Fondue Fulfillment | N24: not stocked | O24: not stocked | P24: not stocked | Q24: not stocked | R24: not stocked
A25: wavestopper-blanket | B25: WaveStopperâ„¢ Blanket | C25: Color | D25: Heather Grey | E25: Fabric | F25: Premium Cotton | G25: Size | H25: Medium 59"x36" | I25: FD2-BLKT-GRY | L25: Basic 3PL | N25: 0 | O25: 0 | P25: 12 | Q25: 232 | R25: 244
A26: wavestopper-blanket | B26: WaveStopperâ„¢ Blanket | C26: Color | D26: Royal Blue | E26: Fabric | F26: Premium Cotton | G26: Size | H26: Medium 59"x36" | I26: FD2-BLKT-NAVY | L26: Shipmonk | N26: 0 | O26: 0 | P26: 0 | Q26: 0 | R26: 0
A27: wavestopper-blanket | B27: WaveStopperâ„¢ Blanket | C27: Color | D27: Royal Blue | E27: Fabric | F27: Premium Cotton | G27: Size | H27: Medium 59"x36" | I27: FD2-BLKT-NAVY | L27: Santa Monica Office | N27: 0 | O27: 0 | P27: 0 | Q27: 0 | R27: 0
A28: wavestopper-blanket | B28: WaveStopperâ„¢ Blanket | C28: Color | D28: Royal Blue | E28: Fabric | F28: Premium Cotton | G28: Size | H28: Medium 59"x36" | I28: FD2-BLKT-NAVY | L28: Fondue Fulfillment | N28: not stocked | O28: not stocked | P28: not stocked | Q28: not stocked | R28: not stocked
A29: wavestopper-blanket | B29: WaveStopperâ„¢ Blanket | C29: Color | D29: Royal Blue | E29: Fabric | F29: Premium Cotton | G29: Size | H29: Medium 59"x36" | I29: FD2-BLKT-NAVY | L29: Basic 3PL | N29: 0 | O29: 0 | P29: 1 | Q29: 0 | R29: 1
A30: wavestopper-blanket | B30: WaveStopperâ„¢ Blanket | C30: Color | D30: Burgundy | E30: Fabric | F30: Premium Cotton | G30: Size | H30: Medium 59"x36" | I30: FD2-BLKT-BORD | L30: Shipmonk | N30: 0 | O30: 0 | P30: 0 | Q30: 0 | R30: 0
A31: wavestopper-blanket | B31: WaveStopperâ„¢ Blanket | C31: Color | D31: Burgundy | E31: Fabric | F31: Premium Cotton | G31: Size | H31: Medium 59"x36" | I31: FD2-BLKT-BORD | L31: Santa Monica Office | N31: 0 | O31: 0 | P31: 0 | Q31: 0 | R31: 0
A32: wavestopper-blanket | B32: WaveStopperâ„¢ Blanket | C32: Color | D32: Burgundy | E32: Fabric | F32: Premium Cotton | G32: Size | H32: Medium 59"x36" | I32: FD2-BLKT-BORD | L32: Fondue Fulfillment | N32: not stocked | O32: not stocked | P32: not stocked | Q32: not stocked | R32: not stocked
A33: wavestopper-blanket | B33: WaveStopperâ„¢ Blanket | C33: Color | D33: Burgundy | E33: Fabric | F33: Premium Cotton | G33: Size | H33: Medium 59"x36" | I33: FD2-BLKT-BORD | L33: Basic 3PL | N33: 0 | O33: 0 | P33: 0 | Q33: 0 | R33: 0
A34: wavestopper-blanket | B34: WaveStopperâ„¢ Blanket | C34: Color | D34: Beige | E34: Fabric | F34: Premium Cotton | G34: Size | H34: Medium 59"x36" | I34: FD2-BLKT-BEI | L34: Shipmonk | N34: 0 | O34: 0 | P34: 0 | Q34: 0 | R34: 0
A35: wavestopper-blanket | B35: WaveStopperâ„¢ Blanket | C35: Color | D35: Beige | E35: Fabric | F35: Premium Cotton | G35: Size | H35: Medium 59"x36" | I35: FD2-BLKT-BEI | L35: Santa Monica Office | N35: 0 | O35: 0 | P35: 0 | Q35: 0 | R35: 0
A36: wavestopper-blanket | B36: WaveStopperâ„¢ Blanket | C36: Color | D36: Beige | E36: Fabric | F36: Premium Cotton | G36: Size | H36: Medium 59"x36" | I36: FD2-BLKT-BEI | L36: Fondue Fulfillment | N36: not stocked | O36: not stocked | P36: not stocked | Q36: not stocked | R36: not stocked
A37: wavestopper-blanket | B37: WaveStopperâ„¢ Blanket | C37: Color | D37: Beige | E37: Fabric | F37: Premium Cotton | G37: Size | H37: Medium 59"x36" | I37: FD2-BLKT-BEI | L37: Basic 3PL | N37: 0 | O37: 0 | P37: 13 | Q37: 196 | R37: 209
A38: wavestopper-blanket | B38: WaveStopperâ„¢ Blanket | C38: Color | D38: Heather Grey | E38: Fabric | F38: Premium Cotton | G38: Size | H38: Large 70"x60" | I38: FD2-BLKT-GRY-LARG | L38: Shipmonk | N38: 0 | O38: 0 | P38: 0 | Q38: 0 | R38: 0
A39: wavestopper-blanket | B39: WaveStopperâ„¢ Blanket | C39: Color | D39: Heather Grey | E39: Fabric | F39: Premium Cotton | G39: Size | H39: Large 70"x60" | I39: FD2-BLKT-GRY-LARG | L39: Santa Monica Office | N39: 0 | O39: 0 | P39: 0 | Q39: 0 | R39: 0
A40: wavestopper-blanket | B40: WaveStopperâ„¢ Blanket | C40: Color | D40: Heather Grey | E40: Fabric | F40: Premium Cotton | G40: Size | H40: Large 70"x60" | I40: FD2-BLKT-GRY-LARG | L40: Fondue Fulfillment | N40: not stocked | O40: not stocked | P40: not stocked | Q40: not stocked | R40: not stocked
...
